#VRML_SIM R2021a utf8
WorldInfo {
  coordinateSystem "NUE"
}
Viewpoint {
  orientation -0.14816875308609231 -0.954439899228592 -0.25901833790183254 2.1420933927806143
  position -2.257102848310226 1.5929889087847175 -1.3069961544841298
}
TexturedBackground {
}
TexturedBackgroundLight {
}
RectangleArena {
  floorSize 100 100
  floorTileSize 0.25 0.25
}
Robot {
  translation 0 0.31 0
  rotation 0 1 0 -5.307179586466759e-06
  children [
    DEF Body Group {
      children [
        Transform {
          children [
            Shape {
              appearance PBRAppearance {
              }
              geometry Box {
                size 0.6 0.02 0.48
              }
            }
          ]
        }
        Transform {
          translation 0 0.05 0.18
          children [
            DEF motor_base Shape {
              appearance PBRAppearance {
                baseColor 1 0 0
              }
              geometry Box {
                size 0.04 0.08 0.08
              }
            }
          ]
        }
        Transform {
          translation 0 0.05 -0.18
          children [
            Shape {
              appearance PBRAppearance {
                baseColor 1 0 0
              }
              geometry Box {
                size 0.04 0.08 0.08
              }
            }
          ]
        }
        Transform {
          translation -0.241716 0.05 0.178284
          rotation 0 1 0 -0.785395307179586
          children [
            Shape {
              appearance PBRAppearance {
                baseColor 1 0 0
              }
              geometry Box {
                size 0.04 0.08 0.08
              }
            }
          ]
        }
        Transform {
          translation 0.246184 0.05 -0.168198
          rotation 0 1 0 -0.785395307179586
          children [
            Shape {
              appearance PBRAppearance {
                baseColor 1 0 0
              }
              geometry Box {
                size 0.04 0.08 0.08
              }
            }
          ]
        }
        Transform {
          translation -0.234645 0.05 -0.18234
          rotation 0 1 0 -2.3561953071795863
          children [
            Shape {
              appearance PBRAppearance {
                baseColor 1 0 0
              }
              geometry Box {
                size 0.04 0.08 0.08
              }
            }
          ]
        }
        Transform {
          translation 0.239115 0.05 0.164142
          rotation 0 1 0 -2.3561953071795863
          children [
            Shape {
              appearance PBRAppearance {
                baseColor 1 0 0
              }
              geometry Box {
                size 0.04 0.08 0.08
              }
            }
          ]
        }
      ]
    }
    HingeJoint {
      jointParameters HingeJointParameters {
        axis 0 1 0
        anchor -0.268 0.1 0.154
      }
      device [
        PositionSensor {
          name "position_sensor_leg2_motor1"
        }
        RotationalMotor {
          name "leg2_motor1"
        }
      ]
      endPoint Solid {
        translation -0.268277 0.0999906 0.196588
        rotation -9.453492014063266e-06 -0.9999999999462124 4.267002984635098e-06 0.7854032344682081
        children [
          DEF motor Shape {
            appearance PBRAppearance {
            }
            geometry Cylinder {
              height 0.02
              radius 0.02
            }
          }
          Solid {
            translation 0 0 0.03
            children [
              DEF leg Group {
                children [
                  Transform {
                    translation 0 0.02 0.06
                    children [
                      DEF green_base Shape {
                        appearance PBRAppearance {
                          baseColor 0 1 0
                        }
                        geometry Box {
                          size 0.12 0.02 0.18
                        }
                      }
                    ]
                  }
                  Transform {
                    translation -6.11772e-08 -0.03 0.13
                    rotation 0 1 0 -1.5707953071795862
                    children [
                      USE motor_base
                    ]
                  }
                ]
              }
              HingeJoint {
                jointParameters HingeJointParameters {
                  anchor 0.05 -0.04 0.13
                }
                device [
                  PositionSensor {
                    name "position_sensor_leg2_motor2"
                  }
                  RotationalMotor {
                    name "leg2_motor2"
                  }
                ]
                endPoint Solid {
                  translation 0.0499672 -0.029971000000000005 0.130002
                  rotation -1.232474889437867e-06 -1.1808981868128912e-05 -0.9999999999295145 1.570795307648649
                  children [
                    USE motor
                    Solid {
                      translation 0 0 0.03
                      children [
                        DEF leg_2 Group {
                          children [
                            Transform {
                              translation 8.29176e-08 0.0199999 0.15
                              rotation -0.5773509358554485 0.5773489358556708 0.5773509358554485 -2.094395307179586
                              children [
                                DEF green_base_long Shape {
                                  appearance PBRAppearance {
                                    baseColor 0 1 0
                                  }
                                  geometry Box {
                                    size 0.02 0.36 0.14
                                  }
                                }
                              ]
                            }
                            Transform {
                              translation 1.10196e-07 -0.03 0.31
                              rotation 0 1 0 1.5708
                              children [
                                USE motor_base
                              ]
                            }
                          ]
                        }
                        HingeJoint {
                          jointParameters HingeJointParameters {
                            axis 0 1 0
                            anchor 0.02 -0.08 0.3
                          }
                          device [
                            PositionSensor {
                              name "position_sensor_leg2_motor3"
                            }
                            RotationalMotor {
                              name "leg2_motor3"
                            }
                          ]
                          endPoint Solid {
                            translation 0.02 -0.08 0.3
                            rotation 0 1 0 1.5707999999999998
                            children [
                              USE motor
                              Solid {
                                translation 0 0 0.04
                                children [
                                  DEF foot Group {
                                    children [
                                      Transform {
                                        translation -7.09499e-09 -0.020001 0.1
                                        rotation 0.5773519358512958 0.5773469358518515 0.5773519358512958 2.0944
                                        children [
                                          Shape {
                                            appearance PBRAppearance {
                                              baseColor 0 1 0
                                            }
                                            geometry Box {
                                              size 0.02 0.28 0.14
                                            }
                                          }
                                        ]
                                      }
                                      Transform {
                                        translation 0 0 0.24
                                        children [
                                          Shape {
                                            appearance PBRAppearance {
                                              baseColor 0 1 0
                                            }
                                            geometry Cylinder {
                                              height 0.02
                                              radius 0.07
                                            }
                                          }
                                        ]
                                      }
                                    ]
                                  }
                                ]
                                boundingObject USE foot
                                physics Physics {
                                }
                              }
                            ]
                            boundingObject USE motor
                            physics Physics {
                            }
                          }
                        }
                      ]
                      boundingObject USE leg_2
                      physics Physics {
                      }
                    }
                  ]
                  boundingObject USE motor
                  physics Physics {
                  }
                }
              }
            ]
            boundingObject USE leg
            physics Physics {
            }
          }
        ]
        boundingObject USE motor
        physics Physics {
        }
      }
    }
    HingeJoint {
      jointParameters HingeJointParameters {
        axis 0 1 0
        anchor 0.259 0.1 0.149
      }
      device [
        PositionSensor {
          name "position_sensor_leg6_motor1"
        }
        RotationalMotor {
          name "leg6_motor1"
        }
      ]
      endPoint Solid {
        translation 0.258732 0.0999623 0.177036
        rotation 2.7188788127543623e-05 0.9999999994617671 -1.836397528646912e-05 0.7853767547796067
        children [
          DEF motor Shape {
            appearance PBRAppearance {
            }
            geometry Cylinder {
              height 0.02
              radius 0.02
            }
          }
          Solid {
            translation 0 0 0.03
            children [
              DEF leg Group {
                children [
                  Transform {
                    translation 0 0.02 0.06
                    children [
                      DEF green_base Shape {
                        appearance PBRAppearance {
                          baseColor 0 1 0
                        }
                        geometry Box {
                          size 0.12 0.02 0.18
                        }
                      }
                    ]
                  }
                  Transform {
                    translation -6.11772e-08 -0.03 0.13
                    rotation 0 1 0 -1.5707953071795862
                    children [
                      USE motor_base
                    ]
                  }
                ]
              }
              HingeJoint {
                jointParameters HingeJointParameters {
                  anchor 0.05 -0.05 0.13
                }
                device [
                  PositionSensor {
                    name "position_sensor_leg6_motor2"
                  }
                  RotationalMotor {
                    name "leg6_motor2"
                  }
                ]
                endPoint Solid {
                  translation 0.05 -0.039999999999999994 0.13
                  rotation 7.85046629564771e-17 0 -0.9999999999999999 1.5707953071795862
                  children [
                    USE motor
                    Solid {
                      translation 0 0 0.03
                      children [
                        DEF leg_2 Group {
                          children [
                            Transform {
                              translation 8.29176e-08 0.0199999 0.15
                              rotation -0.5773509358554485 0.5773489358556708 0.5773509358554485 -2.094395307179586
                              children [
                                DEF green_base_long Shape {
                                  appearance PBRAppearance {
                                    baseColor 0 1 0
                                  }
                                  geometry Box {
                                    size 0.02 0.36 0.14
                                  }
                                }
                              ]
                            }
                            Transform {
                              translation 1.10196e-07 -0.03 0.31
                              rotation 0 1 0 1.5708
                              children [
                                USE motor_base
                              ]
                            }
                          ]
                        }
                        HingeJoint {
                          jointParameters HingeJointParameters {
                            axis 0 1 0
                            anchor 0.02 -0.08 0.3
                          }
                          device [
                            PositionSensor {
                              name "position_sensor_leg6_motor3"
                            }
                            RotationalMotor {
                              name "leg6_motor3"
                            }
                          ]
                          endPoint Solid {
                            translation 0.02 -0.08 0.3
                            rotation 0 1 0 1.5708
                            children [
                              USE motor
                              Solid {
                                translation 0 0 0.04
                                children [
                                  DEF foot Group {
                                    children [
                                      Transform {
                                        translation -7.09499e-09 -0.020001 0.1
                                        rotation 0.5773519358512958 0.5773469358518515 0.5773519358512958 2.0944
                                        children [
                                          Shape {
                                            appearance PBRAppearance {
                                              baseColor 0 1 0
                                            }
                                            geometry Box {
                                              size 0.02 0.28 0.14
                                            }
                                          }
                                        ]
                                      }
                                      Transform {
                                        translation 0 0 0.24
                                        children [
                                          Shape {
                                            appearance PBRAppearance {
                                              baseColor 0 1 0
                                            }
                                            geometry Cylinder {
                                              height 0.02
                                              radius 0.07
                                            }
                                          }
                                        ]
                                      }
                                    ]
                                  }
                                ]
                                boundingObject USE foot
                                physics Physics {
                                }
                              }
                            ]
                            boundingObject USE motor
                            physics Physics {
                            }
                          }
                        }
                      ]
                      boundingObject USE leg_2
                      physics Physics {
                      }
                    }
                  ]
                  boundingObject USE motor
                  physics Physics {
                  }
                }
              }
            ]
            boundingObject USE leg
            physics Physics {
            }
          }
        ]
        name "solid(2)"
        boundingObject USE motor
        physics Physics {
        }
      }
    }
    HingeJoint {
      jointParameters HingeJointParameters {
        axis 0 1 0
        anchor -0.272 0.1 -0.169
      }
      device [
        PositionSensor {
          name "position_sensor_leg1_motor1"
        }
        RotationalMotor {
          name "leg1_motor1"
        }
      ]
      endPoint Solid {
        translation -0.250307 0.100023 -0.190604
        rotation -3.5833957114435903e-07 -0.9999999999925374 -3.846655106901675e-06 2.3561945284795858
        children [
          DEF motor Shape {
            appearance PBRAppearance {
            }
            geometry Cylinder {
              height 0.02
              radius 0.02
            }
          }
          Solid {
            translation 0 0 0.03
            children [
              DEF leg Group {
                children [
                  Transform {
                    translation 0 0.02 0.06
                    children [
                      DEF green_base Shape {
                        appearance PBRAppearance {
                          baseColor 0 1 0
                        }
                        geometry Box {
                          size 0.12 0.02 0.18
                        }
                      }
                    ]
                  }
                  Transform {
                    translation -6.11772e-08 -0.03 0.13
                    rotation 0 1 0 -1.5707953071795862
                    children [
                      USE motor_base
                    ]
                  }
                ]
              }
              HingeJoint {
                jointParameters HingeJointParameters {
                  anchor 0.05 -0.05 0.13
                }
                device [
                  PositionSensor {
                    name "position_sensor_leg1_motor2"
                  }
                  RotationalMotor {
                    name "leg1_motor2"
                  }
                ]
                endPoint Solid {
                  translation 0.05 -0.039999999999999994 0.13
                  rotation 1.2272343017411932e-18 1.226934830218074e-18 -0.9999999999999999 1.5707953071795855
                  children [
                    USE motor
                    Solid {
                      translation 0 0 0.03
                      children [
                        DEF leg_2 Group {
                          children [
                            Transform {
                              translation 8.29176e-08 0.0199999 0.15
                              rotation -0.5773509358554485 0.5773489358556708 0.5773509358554485 -2.094395307179586
                              children [
                                DEF green_base_long Shape {
                                  appearance PBRAppearance {
                                    baseColor 0 1 0
                                  }
                                  geometry Box {
                                    size 0.02 0.36 0.14
                                  }
                                }
                              ]
                            }
                            Transform {
                              translation 1.10196e-07 -0.03 0.31
                              rotation 0 1 0 1.5708
                              children [
                                USE motor_base
                              ]
                            }
                          ]
                        }
                        HingeJoint {
                          jointParameters HingeJointParameters {
                            axis 0 1 0
                            anchor 0.02 -0.08 0.3
                          }
                          device [
                            PositionSensor {
                              name "position_sensor_leg1_motor3"
                            }
                            RotationalMotor {
                              name "leg1_motor3"
                            }
                          ]
                          endPoint Solid {
                            translation 0.02 -0.08 0.3
                            rotation 0 1 0 1.5707999999999998
                            children [
                              USE motor
                              Solid {
                                translation 0 0 0.04
                                children [
                                  DEF foot Group {
                                    children [
                                      Transform {
                                        translation -7.09499e-09 -0.020001 0.1
                                        rotation 0.5773519358512958 0.5773469358518515 0.5773519358512958 2.0944
                                        children [
                                          Shape {
                                            appearance PBRAppearance {
                                              baseColor 0 1 0
                                            }
                                            geometry Box {
                                              size 0.02 0.28 0.14
                                            }
                                          }
                                        ]
                                      }
                                      Transform {
                                        translation 0 0 0.24
                                        children [
                                          Shape {
                                            appearance PBRAppearance {
                                              baseColor 0 1 0
                                            }
                                            geometry Cylinder {
                                              height 0.02
                                              radius 0.07
                                            }
                                          }
                                        ]
                                      }
                                    ]
                                  }
                                ]
                                boundingObject USE foot
                                physics Physics {
                                }
                              }
                            ]
                            boundingObject USE motor
                            physics Physics {
                            }
                          }
                        }
                      ]
                      boundingObject USE leg_2
                      physics Physics {
                      }
                    }
                  ]
                  boundingObject USE motor
                  physics Physics {
                  }
                }
              }
            ]
            boundingObject USE leg
            physics Physics {
            }
          }
        ]
        name "solid(5)"
        boundingObject USE motor
        physics Physics {
        }
      }
    }
    HingeJoint {
      jointParameters HingeJointParameters {
        axis 0 1 0
        anchor 0 0.1 -0.171
      }
      device [
        PositionSensor {
          name "position_sensor_leg3_motor1"
        }
        RotationalMotor {
          name "leg3_motor1"
        }
      ]
      endPoint Solid {
        translation 1.93213e-05 0.100009 -0.201185
        rotation -5.085575607374176e-06 0.9999999999870683 -2.4200152627560113e-08 3.1415983725203134
        children [
          DEF motor Shape {
            appearance PBRAppearance {
            }
            geometry Cylinder {
              height 0.02
              radius 0.02
            }
          }
          Solid {
            translation 0 0 0.03
            children [
              DEF leg Group {
                children [
                  Transform {
                    translation 0 0.02 0.06
                    children [
                      DEF green_base Shape {
                        appearance PBRAppearance {
                          baseColor 0 1 0
                        }
                        geometry Box {
                          size 0.12 0.02 0.18
                        }
                      }
                    ]
                  }
                  Transform {
                    translation -6.11772e-08 -0.03 0.13
                    rotation 0 1 0 -1.5707953071795862
                    children [
                      USE motor_base
                    ]
                  }
                ]
              }
              HingeJoint {
                jointParameters HingeJointParameters {
                  anchor 0.05 -0.05 0.13
                }
                device [
                  PositionSensor {
                    name "position_sensor_leg3_motor2"
                  }
                  RotationalMotor {
                    name "leg3_motor2"
                  }
                ]
                endPoint Solid {
                  translation 0.05 -0.04000000000000001 0.13
                  rotation 0 0 -0.9999999999999999 1.570795307179586
                  children [
                    USE motor
                    Solid {
                      translation 0 0 0.03
                      children [
                        DEF leg_2 Group {
                          children [
                            Transform {
                              translation 8.29176e-08 0.0199999 0.15
                              rotation -0.5773509358554485 0.5773489358556708 0.5773509358554485 -2.094395307179586
                              children [
                                DEF green_base_long Shape {
                                  appearance PBRAppearance {
                                    baseColor 0 1 0
                                  }
                                  geometry Box {
                                    size 0.02 0.36 0.14
                                  }
                                }
                              ]
                            }
                            Transform {
                              translation 1.10196e-07 -0.03 0.31
                              rotation 0 1 0 1.5708
                              children [
                                USE motor_base
                              ]
                            }
                          ]
                        }
                        HingeJoint {
                          jointParameters HingeJointParameters {
                            axis 0 1 0
                            anchor 0.02 -0.08 0.3
                          }
                          device [
                            PositionSensor {
                              name "position_sensor_leg3_motor3"
                            }
                            RotationalMotor {
                              name "leg3_motor3"
                            }
                          ]
                          endPoint Solid {
                            translation 0.02 -0.08 0.3
                            rotation 0 1 0 1.5708
                            children [
                              USE motor
                              Solid {
                                translation 0 0 0.04
                                children [
                                  DEF foot Group {
                                    children [
                                      Transform {
                                        translation -7.09499e-09 -0.020001 0.1
                                        rotation 0.5773519358512958 0.5773469358518515 0.5773519358512958 2.0944
                                        children [
                                          Shape {
                                            appearance PBRAppearance {
                                              baseColor 0 1 0
                                            }
                                            geometry Box {
                                              size 0.02 0.28 0.14
                                            }
                                          }
                                        ]
                                      }
                                      Transform {
                                        translation 0 0 0.24
                                        children [
                                          Shape {
                                            appearance PBRAppearance {
                                              baseColor 0 1 0
                                            }
                                            geometry Cylinder {
                                              height 0.02
                                              radius 0.07
                                            }
                                          }
                                        ]
                                      }
                                    ]
                                  }
                                ]
                                boundingObject USE foot
                                physics Physics {
                                }
                              }
                            ]
                            boundingObject USE motor
                            physics Physics {
                            }
                          }
                        }
                      ]
                      boundingObject USE leg_2
                      physics Physics {
                      }
                    }
                  ]
                  boundingObject USE motor
                  physics Physics {
                  }
                }
              }
            ]
            boundingObject USE leg
            physics Physics {
            }
          }
        ]
        name "solid(4)"
        boundingObject USE motor
        physics Physics {
        }
      }
    }
    HingeJoint {
      jointParameters HingeJointParameters {
        axis 0 1 0
        anchor 0 0.1 0.17
      }
      device [
        PositionSensor {
          name "position_sensor_leg4_motor1"
        }
        RotationalMotor {
          name "leg4_motor1"
        }
      ]
      endPoint Solid {
        translation 5.55112e-06 0.100079 0.199954
        rotation -0.749003283294944 0.6556542903067711 -0.0954543514760748 3.5808987875378146e-05
        children [
          DEF motor Shape {
            appearance PBRAppearance {
            }
            geometry Cylinder {
              height 0.02
              radius 0.02
            }
          }
          Solid {
            translation 0 0 0.03
            children [
              DEF leg Group {
                children [
                  Transform {
                    translation 0 0.02 0.06
                    children [
                      DEF green_base Shape {
                        appearance PBRAppearance {
                          baseColor 0 1 0
                        }
                        geometry Box {
                          size 0.12 0.02 0.18
                        }
                      }
                    ]
                  }
                  Transform {
                    translation -6.11772e-08 -0.03 0.13
                    rotation 0 1 0 -1.5707953071795862
                    children [
                      USE motor_base
                    ]
                  }
                ]
              }
              HingeJoint {
                jointParameters HingeJointParameters {
                  anchor 0.05 -0.05 0.13
                }
                device [
                  PositionSensor {
                    name "position_sensor_leg4_motor2"
                  }
                  RotationalMotor {
                    name "leg4_motor2"
                  }
                ]
                endPoint Solid {
                  translation 0.05 -0.04 0.13
                  rotation -1.2266353586949547e-18 0 -0.9999999999999999 1.5707953071795862
                  children [
                    USE motor
                    Solid {
                      translation 0 0 0.03
                      children [
                        DEF leg_2 Group {
                          children [
                            Transform {
                              translation 8.29176e-08 0.0199999 0.15
                              rotation -0.5773509358554485 0.5773489358556708 0.5773509358554485 -2.094395307179586
                              children [
                                DEF green_base_long Shape {
                                  appearance PBRAppearance {
                                    baseColor 0 1 0
                                  }
                                  geometry Box {
                                    size 0.02 0.36 0.14
                                  }
                                }
                              ]
                            }
                            Transform {
                              translation 1.10196e-07 -0.03 0.31
                              rotation 0 1 0 1.5708
                              children [
                                USE motor_base
                              ]
                            }
                          ]
                        }
                        HingeJoint {
                          jointParameters HingeJointParameters {
                            axis 0 1 0
                            anchor 0.02 -0.08 0.3
                          }
                          device [
                            PositionSensor {
                              name "position_sensor_leg4_motor3"
                            }
                            RotationalMotor {
                              name "leg4_motor3"
                            }
                          ]
                          endPoint Solid {
                            translation 0.02 -0.09 0.3
                            rotation 0 1 0 1.5708
                            children [
                              USE motor
                              Solid {
                                translation 0 0 0.04
                                children [
                                  DEF foot Group {
                                    children [
                                      Transform {
                                        translation -7.09499e-09 -0.020001 0.1
                                        rotation 0.5773519358512958 0.5773469358518515 0.5773519358512958 2.0944
                                        children [
                                          Shape {
                                            appearance PBRAppearance {
                                              baseColor 0 1 0
                                            }
                                            geometry Box {
                                              size 0.02 0.28 0.14
                                            }
                                          }
                                        ]
                                      }
                                      Transform {
                                        translation 0 0 0.24
                                        children [
                                          Shape {
                                            appearance PBRAppearance {
                                              baseColor 0 1 0
                                            }
                                            geometry Cylinder {
                                              height 0.02
                                              radius 0.07
                                            }
                                          }
                                        ]
                                      }
                                    ]
                                  }
                                ]
                                boundingObject USE foot
                                physics Physics {
                                }
                              }
                            ]
                            boundingObject USE motor
                            physics Physics {
                            }
                          }
                        }
                      ]
                      boundingObject USE leg_2
                      physics Physics {
                      }
                    }
                  ]
                  boundingObject USE motor
                  physics Physics {
                  }
                }
              }
            ]
            boundingObject USE leg
            physics Physics {
            }
          }
        ]
        name "solid(1)"
        boundingObject USE motor
        physics Physics {
        }
      }
    }
    HingeJoint {
      jointParameters HingeJointParameters {
        axis 0 1 0
        anchor 0.262 0.1 -0.162
      }
      device [
        PositionSensor {
          name "position_sensor_leg5_motor1"
        }
        RotationalMotor {
          name "leg5_motor1"
        }
      ]
      endPoint Solid {
        translation 0.261632 0.100036 -0.176469
        rotation -8.573716171365127e-06 0.9999999999198306 9.318287125627945e-06 2.3561808100120274
        children [
          DEF motor Shape {
            appearance PBRAppearance {
            }
            geometry Cylinder {
              height 0.02
              radius 0.02
            }
          }
          Solid {
            translation 0 0 0.03
            children [
              DEF leg Group {
                children [
                  Transform {
                    translation 0 0.02 0.06
                    children [
                      DEF green_base Shape {
                        appearance PBRAppearance {
                          baseColor 0 1 0
                        }
                        geometry Box {
                          size 0.12 0.02 0.18
                        }
                      }
                    ]
                  }
                  Transform {
                    translation -6.11772e-08 -0.03 0.13
                    rotation 0 1 0 -1.5707953071795862
                    children [
                      USE motor_base
                    ]
                  }
                ]
              }
              HingeJoint {
                jointParameters HingeJointParameters {
                  anchor 0.05 -0.05 0.13
                }
                device [
                  PositionSensor {
                    name "position_sensor_leg5_motor2"
                  }
                  RotationalMotor {
                    name "leg5_motor2"
                  }
                ]
                endPoint Solid {
                  translation 0.05 -0.04000000000000001 0.13
                  rotation 0 0 -0.9999999999999999 1.5707953071795862
                  children [
                    USE motor
                    Solid {
                      translation 0 0 0.03
                      children [
                        DEF leg_2 Group {
                          children [
                            Transform {
                              translation 8.29176e-08 0.0199999 0.15
                              rotation -0.5773509358554485 0.5773489358556708 0.5773509358554485 -2.094395307179586
                              children [
                                DEF green_base_long Shape {
                                  appearance PBRAppearance {
                                    baseColor 0 1 0
                                  }
                                  geometry Box {
                                    size 0.02 0.36 0.14
                                  }
                                }
                              ]
                            }
                            Transform {
                              translation 1.10196e-07 -0.03 0.31
                              rotation 0 1 0 1.5708
                              children [
                                USE motor_base
                              ]
                            }
                          ]
                        }
                        HingeJoint {
                          jointParameters HingeJointParameters {
                            axis 0 1 0
                            anchor 0.02 -0.08 0.3
                          }
                          device [
                            PositionSensor {
                              name "position_sensor_leg5_motor3"
                            }
                            RotationalMotor {
                              name "leg5_motor3"
                            }
                          ]
                          endPoint Solid {
                            translation 0.02 -0.08 0.3
                            rotation 0 1 0 1.5707999999999998
                            children [
                              USE motor
                              Solid {
                                translation 0 0 0.04
                                children [
                                  DEF foot Group {
                                    children [
                                      Transform {
                                        translation -7.09499e-09 -0.020001 0.1
                                        rotation 0.5773519358512958 0.5773469358518515 0.5773519358512958 2.0944
                                        children [
                                          Shape {
                                            appearance PBRAppearance {
                                              baseColor 0 1 0
                                            }
                                            geometry Box {
                                              size 0.02 0.28 0.14
                                            }
                                          }
                                        ]
                                      }
                                      Transform {
                                        translation 0 0 0.24
                                        children [
                                          Shape {
                                            appearance PBRAppearance {
                                              baseColor 0 1 0
                                            }
                                            geometry Cylinder {
                                              height 0.02
                                              radius 0.07
                                            }
                                          }
                                        ]
                                      }
                                    ]
                                  }
                                ]
                                boundingObject USE foot
                                physics Physics {
                                }
                              }
                            ]
                            boundingObject USE motor
                            physics Physics {
                            }
                          }
                        }
                      ]
                      boundingObject USE leg_2
                      physics Physics {
                      }
                    }
                  ]
                  boundingObject USE motor
                  physics Physics {
                  }
                }
              }
            ]
            boundingObject USE leg
            physics Physics {
            }
          }
        ]
        name "solid(3)"
        boundingObject USE motor
        physics Physics {
        }
      }
    }
  ]
  physics Physics {
  }
  controller "<extern>"
  supervisor TRUE
}
